<mujoco model="linkerhand_l20_8_right">
  <option iterations="50" timestep="0.001" solver="PGS" gravity="0 0 -9.81" />

  <compiler angle="radian" meshdir="meshes" eulerseq="zyx" />

  <default>
    <joint limited="true" damping="0.01" armature="0.01" frictionloss="2.0" />
    <geom condim="4" contype="1" conaffinity="15" friction="2.0 2.0 2.0" solref="0.001 2" />
    <motor ctrllimited="true" />
    <equality solref="0.001 2" />
    <default class="visualgeom">
      <geom material="visualgeom" condim="1" contype="0" conaffinity="0" />
    </default>
  </default>

  <asset>
    <mesh name="base_link" file="linker_hand_l20_8_right/base_link.STL" />
    <mesh name="thumb_link0" file="linker_hand_l20_8_right/thumb_link0.STL" />
    <mesh name="thumb_link1" file="linker_hand_l20_8_right/thumb_link1.STL" />
    <mesh name="thumb_link2" file="linker_hand_l20_8_right/thumb_link2.STL" />
    <mesh name="thumb_link3" file="linker_hand_l20_8_right/thumb_link3.STL" />
    <mesh name="thumb_link4" file="linker_hand_l20_8_right/thumb_link4.STL" />
    <mesh name="thumb_link5" file="linker_hand_l20_8_right/thumb_link5.STL" />
    <mesh name="index_link0" file="linker_hand_l20_8_right/index_link0.STL" />
    <mesh name="index_link1" file="linker_hand_l20_8_right/index_link1.STL" />
    <mesh name="index_link2" file="linker_hand_l20_8_right/index_link2.STL" />
    <mesh name="index_link3" file="linker_hand_l20_8_right/index_link3.STL" />
    <mesh name="index_link4" file="linker_hand_l20_8_right/index_link4.STL" />
    <mesh name="middle_link0" file="linker_hand_l20_8_right/middle_link0.STL" />
    <mesh name="middle_link1" file="linker_hand_l20_8_right/middle_link1.STL" />
    <mesh name="middle_link2" file="linker_hand_l20_8_right/middle_link2.STL" />
    <mesh name="middle_link3" file="linker_hand_l20_8_right/middle_link3.STL" />
    <mesh name="middle_link4" file="linker_hand_l20_8_right/middle_link4.STL" />
    <mesh name="ring_link0" file="linker_hand_l20_8_right/ring_link0.STL" />
    <mesh name="ring_link1" file="linker_hand_l20_8_right/ring_link1.STL" />
    <mesh name="ring_link2" file="linker_hand_l20_8_right/ring_link2.STL" />
    <mesh name="ring_link3" file="linker_hand_l20_8_right/ring_link3.STL" />
    <mesh name="ring_link4" file="linker_hand_l20_8_right/ring_link4.STL" />
    <mesh name="little_link0" file="linker_hand_l20_8_right/little_link0.STL" />
    <mesh name="little_link1" file="linker_hand_l20_8_right/little_link1.STL" />
    <mesh name="little_link2" file="linker_hand_l20_8_right/little_link2.STL" />
    <mesh name="little_link3" file="linker_hand_l20_8_right/little_link3.STL" />
    <mesh name="little_link4" file="linker_hand_l20_8_right/little_link4.STL" />
    <texture name="texplane" type="2d" builtin="checker" rgb1=".0 .0 .0" rgb2=".8 .8 .8" width="100" height="100" />
    <material name="matplane" reflectance="0." texture="texplane" texrepeat="1 1" texuniform="true" />
    <material name="visualgeom" rgba="0.5 0.9 0.2 1" />
    <texture name="matplane" type="2d" builtin="checker" width="512" height="512" rgb1=".1 .2 .3" rgb2=".2 .3 .4"/>
    <material name="matplane" texture="matplane" texrepeat="1 1" texuniform="true" reflectance=".2"/>
  </asset>

  <worldbody>
    <light directional="true" diffuse="0.4 0.4 0.4" specular="0.1 0.1 0.1" pos="0 0 5.0" dir="0 0 -1" castshadow="false" />
    <light directional="true" diffuse="0.6 0.6 0.6" specular="0.2 0.2 0.2" pos="0 0 4" dir="0 0 -1" />

    <geom name="ground" type="plane" size="0 0 .05" quat="1 0 0 0" material="matplane" condim="3" />
    <camera name="fixed" pos="0 -3.0 0.5" xyaxes="1 0 0 0 0 1" />
    <camera name="track" mode="trackcom" pos="0 -3.0 0.5" xyaxes="1 0 0 0 0 1" />
    
    <body name="root" pos="0 0 0.01" quat="1 0 0 0">
      <joint name="base_joint" type="free" /> <!-- 增加base_joint将机LinkerHand固定在地板上 -->
      <site name="imu" size="0.01" pos="0 0 0" />
      <geom type="mesh" rgba="1 1 1 1" mesh="base_link" contype="1" conaffinity="0" density="0" group="1" class="visualgeom" />
      <geom type="mesh" rgba="1 1 1 1" mesh="base_link" />
      <body name="thumb_link0" pos="-0.0025189 0.0050821 0.052292">
        <inertial pos="0.0127889 0.00250561 0.00163117" quat="0.653382 0.714726 0.1516 -0.198183" mass="0.00274798" diaginertia="3.03393e-07 2.76443e-07 9.59634e-08" />
        <joint name="thumb_joint0" pos="0 0 0" axis="1 0 0" range="0 1.57"  />
        <geom type="mesh" rgba="1 1 1 1" mesh="thumb_link0" contype="1" conaffinity="0" density="0" group="1" class="visualgeom" />
        <geom type="mesh" rgba="1 1 1 1" mesh="thumb_link0" />
        <body name="thumb_link1" pos="0.024705 0.00083336 -0.00445" quat="0.99699 0 -0.0775271 0">
          <inertial pos="-0.000388191 0.0129265 0.00568707" quat="0.568511 0.817082 0.0334716 -0.0897315" mass="0.00188085" diaginertia="3.41513e-07 2.93738e-07 7.44257e-08" />
          <joint name="thumb_joint1" pos="0 0 0" axis="0 0 1" range="-1.57 0"  />
          <geom type="mesh" rgba="0.4 0.4 0.4 1" mesh="thumb_link1" contype="1" conaffinity="0" density="0" group="1" class="visualgeom" />
          <geom type="mesh" rgba="0.4 0.4 0.4 1" mesh="thumb_link1" />
          <body name="thumb_link2" pos="0.011959 0.030795 0.0066455" quat="0.99699 0 0.0775271 0">
            <inertial pos="-0.0106232 0.0208042 0.0161569" quat="0.470265 0.88244 -0.0120243 0.00236009" mass="0.0205094" diaginertia="8.50901e-06 7.63494e-06 1.80403e-06" />
            <joint name="thumb_joint2" pos="0 0 0" axis="1 0 0" range="0 1.57"  />
            <geom type="mesh" rgba="1 1 1 1" mesh="thumb_link2" contype="1" conaffinity="0" density="0" group="1" class="visualgeom" />
            <geom type="mesh" rgba="1 1 1 1" mesh="thumb_link2" />
            <body name="thumb_link3" pos="-0.0011 0.044701 0.034112">
              <inertial pos="-0.00937364 0.0118164 0.00400538" quat="0.92791 -0.372734 0.00539935 -0.00475844" mass="0.00483279" diaginertia="6.14155e-07 4.65847e-07 1.99092e-07" />
              <joint name="thumb_joint3" pos="0 0 0" axis="1 0 0" range="0 1.57"  />
              <geom type="mesh" rgba="1 1 1 1" mesh="thumb_link3" contype="1" conaffinity="0" density="0" group="1" class="visualgeom" />
              <geom type="mesh" rgba="1 1 1 1" mesh="thumb_link3" />
              <body name="thumb_link4" pos="-0.01277 0.030981 0.015322">
                <inertial pos="0.00305557 0.0105449 0.00593725" quat="0.615789 0.787904 0.00180099 -0.00288585" mass="0.0065722" diaginertia="5.94673e-07 5.28797e-07 1.64011e-07" />
                <joint name="thumb_joint4" pos="0 0 0" axis="1 0 0" range="0 1.57"  />
                <geom type="mesh" rgba="1 1 1 1" mesh="thumb_link4" contype="1" conaffinity="0" density="0" group="1" class="visualgeom" />
                <geom type="mesh" rgba="1 1 1 1" mesh="thumb_link4" />
                <geom pos="0.0040253 0.030887 0.0073227" type="mesh" rgba="1 1 1 1" mesh="thumb_link5" contype="1" conaffinity="0" density="0" group="1" class="visualgeom" />
                <geom type="mesh" rgba="1 1 1 1" mesh="thumb_link5" pos="0.0040253 0.030887 0.0073227" />
              </body>
            </body>
          </body>
        </body>
      </body>
      <body name="index_link0" pos="-0.028565 0.026698 0.15421">
        <inertial pos="0.00852427 -5.482e-07 0.0022475" quat="0.355185 0.355185 -0.611427 0.611427" mass="0.000858839" diaginertia="4.34042e-08 3.21335e-08 2.50587e-08" />
        <joint name="index_joint0" pos="0 0 0" axis="1 0 0" range="-0.26 0.26"  />
        <geom type="mesh" rgba="1 1 1 1" mesh="index_link0" contype="1" conaffinity="0" density="0" group="1" class="visualgeom" />
        <geom type="mesh" rgba="1 1 1 1" mesh="index_link0" />
        <body name="index_link1" pos="0.013815 0.0047959 0" quat="0.999965 0 0.0083524 0">
          <inertial pos="-0.00107024 -0.00480727 0.0231537" quat="0.706498 -0.0117917 -0.0115837 0.707522" mass="0.00458484" diaginertia="7.20269e-07 7.10518e-07 1.38501e-07" />
          <joint name="index_joint1" pos="0 0 0" axis="0 1 0" range="0 1.57"  />
          <geom type="mesh" rgba="1 1 1 1" mesh="index_link1" contype="1" conaffinity="0" density="0" group="1" class="visualgeom" />
          <geom type="mesh" rgba="1 1 1 1" mesh="index_link1" />
          <body name="index_link2" pos="-0.0041946 -0.0024865 0.044819" quat="0.999965 0 -0.0083524 0">
            <inertial pos="0.00281611 -0.0023741 0.0165998" quat="0.999163 -4.77578e-05 0.0408972 9.28897e-05" mass="0.00240934" diaginertia="2.39021e-07 1.83473e-07 9.72368e-08" />
            <joint name="index_joint2" pos="0 0 0" axis="0 1 0" range="0 1.57"  />
            <geom type="mesh" rgba="1 1 1 1" mesh="index_link2" contype="1" conaffinity="0" density="0" group="1" class="visualgeom" />
            <geom type="mesh" rgba="1 1 1 1" mesh="index_link2" />
            <body name="index_link3" pos="0.0084126 0.0056405 0.03069">
              <inertial pos="-0.00677777 -0.00820941 0.00972138" quat="0.992007 -1.34653e-05 -0.126185 0.000105857" mass="0.00356312" diaginertia="2.50587e-07 2.4395e-07 1.1308e-07" />
              <joint name="index_joint3" pos="0 0 0" axis="0 1 0" range="0 1.57"  />
              <geom type="mesh" rgba="1 1 1 1" mesh="index_link3" contype="1" conaffinity="0" density="0" group="1" class="visualgeom" />
              <geom type="mesh" rgba="1 1 1 1" mesh="index_link3" />
              <geom pos="-0.013709 -0.0073962 0.024981" type="mesh" rgba="1 1 1 1" mesh="index_link4" contype="1" conaffinity="0" density="0" group="1" class="visualgeom" />
              <geom type="mesh" rgba="1 1 1 1" mesh="index_link4" pos="-0.013709 -0.0073962 0.024981" />
            </body>
          </body>
        </body>
      </body>
      <body name="middle_link0" pos="-0.033299 0.0050984 0.1587">
        <inertial pos="0.00852427 -5.47869e-07 0.0022475" quat="0.355185 0.355185 -0.611427 0.611427" mass="0.000858839" diaginertia="4.34042e-08 3.21335e-08 2.50587e-08" />
        <joint name="middle_joint0" pos="0 0 0" axis="1 0 0" range="-0.26 0.26"  />
        <geom type="mesh" rgba="1 1 1 1" mesh="middle_link0" contype="1" conaffinity="0" density="0" group="1" class="visualgeom" />
        <geom type="mesh" rgba="1 1 1 1" mesh="middle_link0" />
        <body name="middle_link1" pos="0.013815 0.0047959 0" quat="0.998134 0 0.061057 0">
          <inertial pos="-0.00350203 -0.00480727 0.0229123" quat="0.704904 -0.049073 -0.0488112 0.705917" mass="0.00458484" diaginertia="7.20269e-07 7.10518e-07 1.38501e-07" />
          <joint name="middle_joint1" pos="0 0 0" axis="0 1 0" range="0 1.57"  />
          <geom type="mesh" rgba="0.4 0.4 0.4 1" mesh="middle_link1" contype="1" conaffinity="0" density="0" group="1" class="visualgeom" />
          <geom type="mesh" rgba="0.4 0.4 0.4 1" mesh="middle_link1" />
          <body name="middle_link2" pos="-0.0088902 -0.0024865 0.044129" quat="0.998134 0 -0.061057 0">
            <inertial pos="0.00281611 -0.0023741 0.0165998" quat="0.999163 -4.77578e-05 0.0408972 9.28897e-05" mass="0.00240934" diaginertia="2.39021e-07 1.83473e-07 9.72368e-08" />
            <joint name="middle_joint2" pos="0 0 0" axis="0 1 0" range="0 1.57"  />
            <geom type="mesh" rgba="1 1 1 1" mesh="middle_link2" contype="1" conaffinity="0" density="0" group="1" class="visualgeom" />
            <geom type="mesh" rgba="1 1 1 1" mesh="middle_link2" />
            <body name="middle_link3" pos="0.0084126 0.0056405 0.03069">
              <inertial pos="-0.00677777 -0.00820941 0.00972138" quat="0.992007 -1.33993e-05 -0.126186 0.000105338" mass="0.00356312" diaginertia="2.50587e-07 2.4395e-07 1.1308e-07" />
              <joint name="middle_joint3" pos="0 0 0" axis="0 1 0" range="0 1.57"  />
              <geom type="mesh" rgba="1 1 1 1" mesh="middle_link3" contype="1" conaffinity="0" density="0" group="1" class="visualgeom" />
              <geom type="mesh" rgba="1 1 1 1" mesh="middle_link3" />
              <geom pos="-0.013709 -0.0073962 0.024981" quat="0.996991 0 -0.0775172 0" type="mesh" rgba="1 1 1 1" mesh="middle_link4" contype="1" conaffinity="0" density="0" group="1" class="visualgeom" />
              <geom type="mesh" rgba="1 1 1 1" mesh="middle_link4" pos="-0.013709 -0.0073962 0.024981" quat="0.996991 0 -0.0775172 0" />
            </body>
          </body>
        </body>
      </body>
      <body name="ring_link0" pos="-0.030994 -0.016502 0.15421">
        <inertial pos="0.00852427 -5.482e-07 0.0022475" quat="0.355185 0.355185 -0.611427 0.611427" mass="0.000858839" diaginertia="4.34042e-08 3.21335e-08 2.50587e-08" />
        <joint name="ring_joint0" pos="0 0 0" axis="1 0 0" range="-0.26 0.26"  />
        <geom type="mesh" rgba="1 1 1 1" mesh="ring_link0" contype="1" conaffinity="0" density="0" group="1" class="visualgeom" />
        <geom type="mesh" rgba="1 1 1 1" mesh="ring_link0" />
        <body name="ring_link1" pos="0.013815 0.0047959 0" quat="0.998134 0 0.061057 0">
          <inertial pos="-0.00350203 -0.00480727 0.0229123" quat="0.704904 -0.049073 -0.0488112 0.705917" mass="0.00458484" diaginertia="7.20269e-07 7.10518e-07 1.38501e-07" />
          <joint name="ring_joint1" pos="0 0 0" axis="0 1 0" range="0 1.57"  />
          <geom type="mesh" rgba="1 1 1 1" mesh="ring_link1" contype="1" conaffinity="0" density="0" group="1" class="visualgeom" />
          <geom type="mesh" rgba="1 1 1 1" mesh="ring_link1" />
          <body name="ring_link2" pos="-0.0088902 -0.0024865 0.044129" quat="0.998134 0 -0.061057 0">
            <inertial pos="0.00281611 -0.0023741 0.0165998" quat="0.999163 -4.77578e-05 0.0408972 9.28897e-05" mass="0.00240934" diaginertia="2.39021e-07 1.83473e-07 9.72368e-08" />
            <joint name="ring_joint2" pos="0 0 0" axis="0 1 0" range="0 1.57"  />
            <geom type="mesh" rgba="1 1 1 1" mesh="ring_link2" contype="1" conaffinity="0" density="0" group="1" class="visualgeom" />
            <geom type="mesh" rgba="1 1 1 1" mesh="ring_link2" />
            <body name="ring_link3" pos="0.0084126 0.0056405 0.03069">
              <inertial pos="-0.00677777 -0.00820942 0.00972139" quat="0.992007 -1.3371e-05 -0.126185 0.000105116" mass="0.00356312" diaginertia="2.50588e-07 2.4395e-07 1.1308e-07" />
              <joint name="ring_joint3" pos="0 0 0" axis="0 1 0" range="0 1.57"  />
              <geom type="mesh" rgba="1 1 1 1" mesh="ring_link3" contype="1" conaffinity="0" density="0" group="1" class="visualgeom" />
              <geom type="mesh" rgba="1 1 1 1" mesh="ring_link3" />
              <geom pos="-0.013709 -0.0073962 0.024981" type="mesh" rgba="1 1 1 1" mesh="ring_link4" contype="1" conaffinity="0" density="0" group="1" class="visualgeom" />
              <geom type="mesh" rgba="1 1 1 1" mesh="ring_link4" pos="-0.013709 -0.0073962 0.024981" />
            </body>
          </body>
        </body>
      </body>
      <body name="little_link0" pos="-0.02737 -0.038102 0.14521">
        <inertial pos="0.00852427 -5.47869e-07 0.0022475" quat="0.355185 0.355185 -0.611427 0.611427" mass="0.000858839" diaginertia="4.34042e-08 3.21335e-08 2.50587e-08" />
        <joint name="little_joint0" pos="0 0 0" axis="1 0 0" range="-0.26 0.26"  />
        <geom type="mesh" rgba="1 1 1 1" mesh="little_link0" contype="1" conaffinity="0" density="0" group="1" class="visualgeom" />
        <geom type="mesh" rgba="1 1 1 1" mesh="little_link0" />
        <body name="little_link1" pos="0.013815 0.0047959 0" quat="0.998134 0 0.061057 0">
          <inertial pos="-0.00350203 -0.00480727 0.0229123" quat="0.704904 -0.049073 -0.0488112 0.705917" mass="0.00458484" diaginertia="7.20269e-07 7.10518e-07 1.38501e-07" />
          <joint name="little_joint1" pos="0 0 0" axis="0 1 0" range="0 1.57"  />
          <geom type="mesh" rgba="1 1 1 1" mesh="little_link1" contype="1" conaffinity="0" density="0" group="1" class="visualgeom" />
          <geom type="mesh" rgba="1 1 1 1" mesh="little_link1" />
          <body name="little_link2" pos="-0.0088902 -0.0024865 0.044129" quat="0.998134 0 -0.061057 0">
            <inertial pos="0.00281611 -0.0023741 0.0165998" quat="0.999163 -4.77578e-05 0.0408972 9.28897e-05" mass="0.00240934" diaginertia="2.39021e-07 1.83473e-07 9.72368e-08" />
            <joint name="little_joint2" pos="0 0 0" axis="0 1 0" range="0 1.57"  />
            <geom type="mesh" rgba="1 1 1 1" mesh="little_link2" contype="1" conaffinity="0" density="0" group="1" class="visualgeom" />
            <geom type="mesh" rgba="1 1 1 1" mesh="little_link2" />
            <body name="little_link3" pos="0.0084126 0.0056405 0.03069">
              <inertial pos="-0.00677777 -0.00820941 0.00972139" quat="0.992007 -1.28715e-05 -0.126186 0.000101189" mass="0.00356312" diaginertia="2.50588e-07 2.43951e-07 1.1308e-07" />
              <joint name="little_joint3" pos="0 0 0" axis="0 1 0" range="0 1.57"  />
              <geom type="mesh" rgba="1 1 1 1" mesh="little_link3" contype="1" conaffinity="0" density="0" group="1" class="visualgeom" />
              <geom type="mesh" rgba="1 1 1 1" mesh="little_link3" />
              <geom pos="-0.013709 -0.0073962 0.024981" quat="0.996991 0 -0.0775172 0" type="mesh" rgba="1 1 1 1" mesh="little_link4" contype="1" conaffinity="0" density="0" group="1" class="visualgeom" />
              <geom type="mesh" rgba="1 1 1 1" mesh="little_link4" pos="-0.013709 -0.0073962 0.024981" quat="0.996991 0 -0.0775172 0" />
            </body>
          </body>
        </body>
      </body>
    </body>
  </worldbody>
  <option gravity="0 0 -9.81"/>
  <actuator>
    <motor name="thumb_joint0" joint="thumb_joint0" ctrllimited="true" ctrlrange="-100 100" gear="1" />
    <motor name="thumb_joint1" joint="thumb_joint1" ctrllimited="true" ctrlrange="-100 100" gear="1" />
    <motor name="thumb_joint2" joint="thumb_joint2" ctrllimited="true" ctrlrange="-100 100" gear="1" />
    <motor name="thumb_joint3" joint="thumb_joint3" ctrllimited="true" ctrlrange="-100 100" gear="1" />
    <motor name="thumb_joint4" joint="thumb_joint4" ctrllimited="true" ctrlrange="-100 100" gear="1" />
    <motor name="index_joint0" joint="index_joint0" ctrllimited="true" ctrlrange="-100 100" gear="1" />
    <motor name="index_joint1" joint="index_joint1" ctrllimited="true" ctrlrange="-100 100" gear="1" />
    <motor name="index_joint2" joint="index_joint2" ctrllimited="true" ctrlrange="-100 100" gear="1" />
    <motor name="index_joint3" joint="index_joint3" ctrllimited="true" ctrlrange="-100 100" gear="1" />
    <motor name="middle_joint0" joint="middle_joint0" ctrllimited="true" ctrlrange="-100 100" gear="1" />
    <motor name="middle_joint1" joint="middle_joint1" ctrllimited="true" ctrlrange="-100 100" gear="1" />
    <motor name="middle_joint2" joint="middle_joint2" ctrllimited="true" ctrlrange="-100 100" gear="1" />
    <motor name="middle_joint3" joint="middle_joint3" ctrllimited="true" ctrlrange="-100 100" gear="1" />
    <motor name="ring_joint0" joint="ring_joint0" ctrllimited="true" ctrlrange="-100 100" gear="1" />
    <motor name="ring_joint1" joint="ring_joint1" ctrllimited="true" ctrlrange="-100 100" gear="1" />
    <motor name="ring_joint2" joint="ring_joint2" ctrllimited="true" ctrlrange="-100 100" gear="1" />
    <motor name="ring_joint3" joint="ring_joint3" ctrllimited="true" ctrlrange="-100 100" gear="1" />
    <motor name="little_joint0" joint="little_joint0" ctrllimited="true" ctrlrange="-100 100" gear="1" />
    <motor name="little_joint1" joint="little_joint1" ctrllimited="true" ctrlrange="-100 100" gear="1" />
    <motor name="little_joint2" joint="little_joint2" ctrllimited="true" ctrlrange="-100 100" gear="1" />
    <motor name="little_joint3" joint="little_joint3" ctrllimited="true" ctrlrange="-100 100" gear="1" />
  </actuator>

  <sensor>
    <actuatorpos name="thumb_joint0_p" actuator="thumb_joint0" />
    <actuatorvel name="thumb_joint0_v" actuator="thumb_joint0" />
    <actuatorfrc name="thumb_joint0_f" actuator="thumb_joint0" noise="0.001" />
    <actuatorpos name="thumb_joint1_p" actuator="thumb_joint1" />
    <actuatorvel name="thumb_joint1_v" actuator="thumb_joint1" />
    <actuatorfrc name="thumb_joint1_f" actuator="thumb_joint1" noise="0.001" />
    <actuatorpos name="thumb_joint2_p" actuator="thumb_joint2" />
    <actuatorvel name="thumb_joint2_v" actuator="thumb_joint2" />
    <actuatorfrc name="thumb_joint2_f" actuator="thumb_joint2" noise="0.001" />
    <actuatorpos name="thumb_joint3_p" actuator="thumb_joint3" />
    <actuatorvel name="thumb_joint3_v" actuator="thumb_joint3" />
    <actuatorfrc name="thumb_joint3_f" actuator="thumb_joint3" noise="0.001" />
    <actuatorpos name="thumb_joint4_p" actuator="thumb_joint4" />
    <actuatorvel name="thumb_joint4_v" actuator="thumb_joint4" />
    <actuatorfrc name="thumb_joint4_f" actuator="thumb_joint4" noise="0.001" />
    <actuatorpos name="index_joint0_p" actuator="index_joint0" />
    <actuatorvel name="index_joint0_v" actuator="index_joint0" />
    <actuatorfrc name="index_joint0_f" actuator="index_joint0" noise="0.001" />
    <actuatorpos name="index_joint1_p" actuator="index_joint1" />
    <actuatorvel name="index_joint1_v" actuator="index_joint1" />
    <actuatorfrc name="index_joint1_f" actuator="index_joint1" noise="0.001" />
    <actuatorpos name="index_joint2_p" actuator="index_joint2" />
    <actuatorvel name="index_joint2_v" actuator="index_joint2" />
    <actuatorfrc name="index_joint2_f" actuator="index_joint2" noise="0.001" />
    <actuatorpos name="index_joint3_p" actuator="index_joint3" />
    <actuatorvel name="index_joint3_v" actuator="index_joint3" />
    <actuatorfrc name="index_joint3_f" actuator="index_joint3" noise="0.001" />
    <actuatorpos name="middle_joint0_p" actuator="middle_joint0" />
    <actuatorvel name="middle_joint0_v" actuator="middle_joint0" />
    <actuatorfrc name="middle_joint0_f" actuator="middle_joint0" noise="0.001" />
    <actuatorpos name="middle_joint1_p" actuator="middle_joint1" />
    <actuatorvel name="middle_joint1_v" actuator="middle_joint1" />
    <actuatorfrc name="middle_joint1_f" actuator="middle_joint1" noise="0.001" />
    <actuatorpos name="middle_joint2_p" actuator="middle_joint2" />
    <actuatorvel name="middle_joint2_v" actuator="middle_joint2" />
    <actuatorfrc name="middle_joint2_f" actuator="middle_joint2" noise="0.001" />
    <actuatorpos name="middle_joint3_p" actuator="middle_joint3" />
    <actuatorvel name="middle_joint3_v" actuator="middle_joint3" />
    <actuatorfrc name="middle_joint3_f" actuator="middle_joint3" noise="0.001" />
    <actuatorpos name="ring_joint0_p" actuator="ring_joint0" />
    <actuatorvel name="ring_joint0_v" actuator="ring_joint0" />
    <actuatorfrc name="ring_joint0_f" actuator="ring_joint0" noise="0.001" />
    <actuatorpos name="ring_joint1_p" actuator="ring_joint1" />
    <actuatorvel name="ring_joint1_v" actuator="ring_joint1" />
    <actuatorfrc name="ring_joint1_f" actuator="ring_joint1" noise="0.001" />
    <actuatorpos name="ring_joint2_p" actuator="ring_joint2" />
    <actuatorvel name="ring_joint2_v" actuator="ring_joint2" />
    <actuatorfrc name="ring_joint2_f" actuator="ring_joint2" noise="0.001" />
    <actuatorpos name="ring_joint3_p" actuator="ring_joint3" />
    <actuatorvel name="ring_joint3_v" actuator="ring_joint3" />
    <actuatorfrc name="ring_joint3_f" actuator="ring_joint3" noise="0.001" />
    <actuatorpos name="little_joint0_p" actuator="little_joint0" />
    <actuatorvel name="little_joint0_v" actuator="little_joint0" />
    <actuatorfrc name="little_joint0_f" actuator="little_joint0" noise="0.001" />
    <actuatorpos name="little_joint1_p" actuator="little_joint1" />
    <actuatorvel name="little_joint1_v" actuator="little_joint1" />
    <actuatorfrc name="little_joint1_f" actuator="little_joint1" noise="0.001" />
    <actuatorpos name="little_joint2_p" actuator="little_joint2" />
    <actuatorvel name="little_joint2_v" actuator="little_joint2" />
    <actuatorfrc name="little_joint2_f" actuator="little_joint2" noise="0.001" />
    <actuatorpos name="little_joint3_p" actuator="little_joint3" />
    <actuatorvel name="little_joint3_v" actuator="little_joint3" />
    <actuatorfrc name="little_joint3_f" actuator="little_joint3" noise="0.001" />
    <framequat name="orientation" objtype="site" noise="0.001" objname="imu" />
    <gyro name="angular-velocity" site="imu" noise="0.005" cutoff="34.9" />
  </sensor>
</mujoco>