<mujoco model="l20_8_l">
  <option iterations="50" timestep="0.001" solver="PGS" gravity="0 0 -9.81" />

  <compiler angle="radian" meshdir="meshes" eulerseq="zyx" />

  <default>
    <joint limited="true" damping="0.01" armature="0.01" frictionloss="2.0" />
    <geom condim="4" contype="1" conaffinity="15" friction="2.0 2.0 2.0" solref="0.001 2" />
    <motor ctrllimited="true" />
    <equality solref="0.001 2" />
    <default class="visualgeom">
      <geom material="visualgeom" condim="1" contype="0" conaffinity="0" />
    </default>
  </default>

  <asset>
    <mesh name="base_link" file="linker_hand_l20_8_left/base_link.STL" />
    <mesh name="thumb_link0" file="linker_hand_l20_8_left/thumb_link0.STL" />
    <mesh name="thumb_link1" file="linker_hand_l20_8_left/thumb_link1.STL" />
    <mesh name="thumb_link2" file="linker_hand_l20_8_left/thumb_link2.STL" />
    <mesh name="thumb_link3" file="linker_hand_l20_8_left/thumb_link3.STL" />
    <mesh name="thumb_link4" file="linker_hand_l20_8_left/thumb_link4.STL" />
    <mesh name="thumb_link5" file="linker_hand_l20_8_left/thumb_link5.STL" />
    <mesh name="index_link0" file="linker_hand_l20_8_left/index_link0.STL" />
    <mesh name="index_link1" file="linker_hand_l20_8_left/index_link1.STL" />
    <mesh name="index_link2" file="linker_hand_l20_8_left/index_link2.STL" />
    <mesh name="index_link3" file="linker_hand_l20_8_left/index_link3.STL" />
    <mesh name="index_link4" file="linker_hand_l20_8_left/index_link4.STL" />
    <mesh name="middle_link0" file="linker_hand_l20_8_left/middle_link0.STL" />
    <mesh name="middle_link1" file="linker_hand_l20_8_left/middle_link1.STL" />
    <mesh name="middle_link2" file="linker_hand_l20_8_left/middle_link2.STL" />
    <mesh name="middle_link3" file="linker_hand_l20_8_left/middle_link3.STL" />
    <mesh name="middle_link4" file="linker_hand_l20_8_left/middle_link4.STL" />
    <mesh name="ring_link0" file="linker_hand_l20_8_left/ring_link0.STL" />
    <mesh name="ring_link1" file="linker_hand_l20_8_left/ring_link1.STL" />
    <mesh name="ring_link2" file="linker_hand_l20_8_left/ring_link2.STL" />
    <mesh name="ring_link3" file="linker_hand_l20_8_left/ring_link3.STL" />
    <mesh name="ring_link4" file="linker_hand_l20_8_left/ring_link4.STL" />
    <mesh name="little_link0" file="linker_hand_l20_8_left/little_link0.STL" />
    <mesh name="little_link1" file="linker_hand_l20_8_left/little_link1.STL" />
    <mesh name="little_link2" file="linker_hand_l20_8_left/little_link2.STL" />
    <mesh name="little_link3" file="linker_hand_l20_8_left/little_link3.STL" />
    <mesh name="little_link4" file="linker_hand_l20_8_left/little_link4.STL" />
    <texture name="texplane" type="2d" builtin="checker" rgb1=".0 .0 .0" rgb2=".8 .8 .8" width="100" height="100" />
    <!-- <material name="matplane" reflectance="0." texture="texplane" texrepeat="1 1" texuniform="true" /> -->
    <material name="visualgeom" rgba="0.5 0.9 0.2 1" />
    <texture name="matplane" type="2d" builtin="checker" width="512" height="512" rgb1=".1 .2 .3" rgb2=".2 .3 .4"/>
    <material name="matplane" texture="matplane" texrepeat="1 1" texuniform="true" reflectance=".2"/>
  </asset>

  <worldbody>
    <light directional="true" diffuse="0.4 0.4 0.4" specular="0.1 0.1 0.1" pos="0 0 5.0" dir="0 0 -1" castshadow="false" />
    <light directional="true" diffuse="0.6 0.6 0.6" specular="0.2 0.2 0.2" pos="0 0 4" dir="0 0 -1" />

    <geom name="ground" type="plane" size="0 0 .05" quat="1 0 0 0" material="matplane" condim="3" />
    <camera name="fixed" pos="0 -3.0 0.5" xyaxes="1 0 0 0 0 1" />
    <camera name="track" mode="trackcom" pos="0 -3.0 0.5" xyaxes="1 0 0 0 0 1" />
    
    <body name="root" pos="0 0 0.01" quat="1 0 0 0">
      <joint name="base_joint" type="free" /> <!-- 增加base_joint将机LinkerHand固定在地板上 -->
      <site name="imu" size="0.01" pos="0 0 0" />
      <geom type="mesh" rgba="1 1 1 1" mesh="base_link" contype="1" conaffinity="0" density="0" group="1" class="visualgeom" />
      <geom type="mesh" rgba="1 1 1 1" mesh="base_link" />
      <body name="thumb_link0" pos="-0.0025188 -0.0050821 0.052292">
        <inertial pos="0.0127888 -0.0025056 0.0016311" quat="0.714728 0.653385 0.198173 -0.151588" mass="0.002748" diaginertia="3.03396e-07 2.76444e-07 9.59657e-08" />
        <joint name="thumb_joint0" pos="0 0 0" axis="1 0 0" range="-1.57 0" actuatorfrcrange="-100 100" />
        <geom type="mesh" rgba="1 1 1 1" mesh="thumb_link0" contype="1" conaffinity="0" density="0" group="1" class="visualgeom" />
        <geom type="mesh" rgba="1 1 1 1" mesh="thumb_link0" />
        <body name="thumb_link1" pos="0.024508 -0.00083332 -0.00845">
          <inertial pos="-0.00106505 -0.0129271 0.00955894" quat="0.821578 0.569398 0.0261064 0.0106998" mass="0.00188076" diaginertia="3.41494e-07 2.93718e-07 7.44231e-08" />
          <joint name="thumb_joint1" pos="0 0 0" axis="0 0 1" range="0 1.57" actuatorfrcrange="-100 100" />
          <geom type="mesh" rgba="1 1 1 1" mesh="thumb_link1" contype="1" conaffinity="0" density="0" group="1" class="visualgeom" />
          <geom type="mesh" rgba="1 1 1 1" mesh="thumb_link1" />
          <body name="thumb_link2" pos="0.010985 -0.030795 0.012414">
            <inertial pos="-0.0106242 -0.0208034 0.0161575" quat="0.882449 0.470244 -0.00244079 0.0121843" mass="0.0205071" diaginertia="8.50825e-06 7.63476e-06 1.80325e-06" />
            <joint name="thumb_joint2" pos="0 0 0" axis="1 0 0" range="-1 0" actuatorfrcrange="-100 100" />
            <geom type="mesh" rgba="1 1 1 1" mesh="thumb_link2" contype="1" conaffinity="0" density="0" group="1" class="visualgeom" />
            <geom type="mesh" rgba="1 1 1 1" mesh="thumb_link2" />
            <body name="thumb_link3" pos="-0.0010999 -0.044701 0.034112">
              <inertial pos="-0.00937367 -0.0118165 0.00400539" quat="0.92791 0.372735 0.00539991 0.00476082" mass="0.00483281" diaginertia="6.14158e-07 4.65849e-07 1.99093e-07" />
              <joint name="thumb_joint3" pos="0 0 0" axis="1 0 0" range="-1.57 0" actuatorfrcrange="-100 100" />
              <geom type="mesh" rgba="1 1 1 1" mesh="thumb_link3" contype="1" conaffinity="0" density="0" group="1" class="visualgeom" />
              <geom type="mesh" rgba="1 1 1 1" mesh="thumb_link3" />
              <body name="thumb_link4" pos="-0.01277 -0.030981 0.015322">
                <inertial pos="0.00305603 -0.0105449 0.00593707" quat="0.787919 0.615769 0.00295912 -0.00185785" mass="0.00657183" diaginertia="5.94643e-07 5.28775e-07 1.63999e-07" />
                <joint name="thumb_joint4" pos="0 0 0" axis="1 0 0" range="-1.57 0" actuatorfrcrange="-100 100" />
                <geom type="mesh" rgba="1 1 1 1" mesh="thumb_link4" contype="1" conaffinity="0" density="0" group="1" class="visualgeom" />
                <geom type="mesh" rgba="1 1 1 1" mesh="thumb_link4" />
                <geom pos="0.0040254 -0.030887 0.0073227" type="mesh" rgba="1 1 1 1" mesh="thumb_link5" contype="1" conaffinity="0" density="0" group="1" class="visualgeom" />
                <geom type="mesh" rgba="1 1 1 1" mesh="thumb_link5" pos="0.0040254 -0.030887 0.0073227" />
              </body>
            </body>
          </body>
        </body>
      </body>
      <body name="index_link0" pos="-0.025865 -0.026698 0.15421">
        <inertial pos="0.00582427 5.50368e-07 0.0022475" quat="0.355185 0.355185 -0.611427 0.611427" mass="0.000858839" diaginertia="4.34042e-08 3.21335e-08 2.50587e-08" />
        <joint name="index_joint0" pos="0 0 0" axis="1 0 0" range="-0.26 0.26" actuatorfrcrange="-100 100" />
        <geom type="mesh" rgba="1 1 1 1" mesh="index_link0" contype="1" conaffinity="0" density="0" group="1" class="visualgeom" />
        <geom type="mesh" rgba="1 1 1 1" mesh="index_link0" />
        <body name="index_link1" pos="0.011115 -0.0047959 0">
          <inertial pos="-0.000683356 0.0048078 0.0243018" quat="0.707512 -0.00568475 -0.00587904 0.706654" mass="0.00458484" diaginertia="7.20266e-07 7.10515e-07 1.385e-07" />
          <joint name="index_joint1" pos="0 0 0" axis="0 1 0" range="0 1.57" actuatorfrcrange="-100 100" />
          <geom type="mesh" rgba="1 1 1 1" mesh="index_link1" contype="1" conaffinity="0" density="0" group="1" class="visualgeom" />
          <geom type="mesh" rgba="1 1 1 1" mesh="index_link1" />
          <body name="index_link2" pos="-0.0034454 0.0010465 0.044883">
            <inertial pos="0.00281619 0.00381383 0.0165996" quat="0.999163 2.62805e-05 0.0409006 -6.95714e-05" mass="0.00240942" diaginertia="2.39031e-07 1.8348e-07 9.72399e-08" />
            <joint name="index_joint2" pos="0 0 0" axis="0 1 0" range="0 1.57" actuatorfrcrange="-100 100" />
            <geom type="mesh" rgba="1 1 1 1" mesh="index_link2" contype="1" conaffinity="0" density="0" group="1" class="visualgeom" />
            <geom type="mesh" rgba="1 1 1 1" mesh="index_link2" />
            <body name="index_link3" pos="0.0084126 -0.0012 0.03069">
              <inertial pos="-0.00677812 0.00520866 0.00972347" quat="0.992008 3.57322e-05 -0.126178 -0.000280925" mass="0.00356381" diaginertia="2.50693e-07 2.44047e-07 1.13074e-07" />
              <joint name="index_joint3" pos="0 0 0" axis="0 1 0" range="0 1.57" actuatorfrcrange="-100 100" />
              <geom type="mesh" rgba="1 1 1 1" mesh="index_link3" contype="1" conaffinity="0" density="0" group="1" class="visualgeom" />
              <geom type="mesh" rgba="1 1 1 1" mesh="index_link3" />
              <geom pos="-0.013709 0.0063957 0.024981" type="mesh" rgba="1 1 1 1" mesh="index_link4" contype="1" conaffinity="0" density="0" group="1" class="visualgeom" />
              <geom type="mesh" rgba="1 1 1 1" mesh="index_link4" pos="-0.013709 0.0063957 0.024981" />
            </body>
          </body>
        </body>
      </body>
      <body name="middle_link0" pos="-0.030599 -0.0050984 0.1587">
        <inertial pos="0.00582427 5.60656e-07 0.0022475" quat="0.355185 0.355185 -0.611427 0.611427" mass="0.000858839" diaginertia="4.34042e-08 3.21335e-08 2.50587e-08" />
        <joint name="middle_joint0" pos="0 0 0" axis="1 0 0" range="-0.26 0.26" actuatorfrcrange="-100 100" />
        <geom type="mesh" rgba="1 1 1 1" mesh="middle_link0" contype="1" conaffinity="0" density="0" group="1" class="visualgeom" />
        <geom type="mesh" rgba="1 1 1 1" mesh="middle_link0" />
        <body name="middle_link1" pos="0.011115 -0.0047959 0">
          <inertial pos="-0.000683358 0.00480779 0.0243018" quat="0.707512 -0.00568485 -0.00587906 0.706654" mass="0.00458484" diaginertia="7.20267e-07 7.10516e-07 1.385e-07" />
          <joint name="middle_joint1" pos="0 0 0" axis="0 1 0" range="0 1.57" actuatorfrcrange="-100 100" />
          <geom type="mesh" rgba="1 1 1 1" mesh="middle_link1" contype="1" conaffinity="0" density="0" group="1" class="visualgeom" />
          <geom type="mesh" rgba="1 1 1 1" mesh="middle_link1" />
          <body name="middle_link2" pos="-0.0034454 0.0010465 0.044883">
            <inertial pos="0.00281619 0.00381383 0.0165996" quat="0.999163 2.62805e-05 0.0409006 -6.95714e-05" mass="0.00240942" diaginertia="2.39031e-07 1.8348e-07 9.72399e-08" />
            <joint name="middle_joint2" pos="0 0 0" axis="0 1 0" range="0 1.57" actuatorfrcrange="-100 100" />
            <geom type="mesh" rgba="1 1 1 1" mesh="middle_link2" contype="1" conaffinity="0" density="0" group="1" class="visualgeom" />
            <geom type="mesh" rgba="1 1 1 1" mesh="middle_link2" />
            <body name="middle_link3" pos="0.0084126 -0.0012 0.03069">
              <inertial pos="-0.00677812 0.00520866 0.00972347" quat="0.992008 3.57659e-05 -0.126178 -0.00028119" mass="0.00356381" diaginertia="2.50693e-07 2.44047e-07 1.13074e-07" />
              <joint name="middle_joint3" pos="0 0 0" axis="0 1 0" range="0 1.57" actuatorfrcrange="-100 100" />
              <geom type="mesh" rgba="1 1 1 1" mesh="middle_link3" contype="1" conaffinity="0" density="0" group="1" class="visualgeom" />
              <geom type="mesh" rgba="1 1 1 1" mesh="middle_link3" />
              <geom pos="-0.013709 0.0063957 0.024981" type="mesh" rgba="1 1 1 1" mesh="middle_link4" contype="1" conaffinity="0" density="0" group="1" class="visualgeom" />
              <geom type="mesh" rgba="1 1 1 1" mesh="middle_link4" pos="-0.013709 0.0063957 0.024981" />
            </body>
          </body>
        </body>
      </body>
      <body name="ring_link0" pos="-0.028294 0.016502 0.15421">
        <inertial pos="0.00582427 5.60656e-07 0.0022475" quat="0.355185 0.355185 -0.611427 0.611427" mass="0.000858839" diaginertia="4.34042e-08 3.21335e-08 2.50587e-08" />
        <joint name="ring_joint0" pos="0 0 0" axis="1 0 0" range="-0.26 0.26" actuatorfrcrange="-100 100" />
        <geom type="mesh" rgba="1 1 1 1" mesh="ring_link0" contype="1" conaffinity="0" density="0" group="1" class="visualgeom" />
        <geom type="mesh" rgba="1 1 1 1" mesh="ring_link0" />
        <body name="ring_link1" pos="0.011115 -0.0047959 0">
          <inertial pos="-0.000683358 0.0048078 0.0243018" quat="0.707513 -0.00568489 -0.0058791 0.706653" mass="0.00458484" diaginertia="7.20267e-07 7.10516e-07 1.385e-07" />
          <joint name="ring_joint1" pos="0 0 0" axis="0 1 0" range="0 1.57" actuatorfrcrange="-100 100" />
          <geom type="mesh" rgba="1 1 1 1" mesh="ring_link1" contype="1" conaffinity="0" density="0" group="1" class="visualgeom" />
          <geom type="mesh" rgba="1 1 1 1" mesh="ring_link1" />
          <body name="ring_link2" pos="-0.0034454 0.0010465 0.044883">
            <inertial pos="0.00281619 0.00381383 0.0165996" quat="0.999163 2.62805e-05 0.0409006 -6.95714e-05" mass="0.00240942" diaginertia="2.39031e-07 1.8348e-07 9.72399e-08" />
            <joint name="ring_joint2" pos="0 0 0" axis="0 1 0" range="0 1.57" actuatorfrcrange="-100 100" />
            <geom type="mesh" rgba="1 1 1 1" mesh="ring_link2" contype="1" conaffinity="0" density="0" group="1" class="visualgeom" />
            <geom type="mesh" rgba="1 1 1 1" mesh="ring_link2" />
            <body name="ring_link3" pos="0.0084126 -0.0012 0.03069">
              <inertial pos="-0.00677812 0.00520865 0.00972345" quat="0.992008 3.56333e-05 -0.126178 -0.000280147" mass="0.00356381" diaginertia="2.50693e-07 2.44048e-07 1.13074e-07" />
              <joint name="ring_joint3" pos="0 0 0" axis="0 1 0" range="0 1.57" actuatorfrcrange="-100 100" />
              <geom type="mesh" rgba="1 1 1 1" mesh="ring_link3" contype="1" conaffinity="0" density="0" group="1" class="visualgeom" />
              <geom type="mesh" rgba="1 1 1 1" mesh="ring_link3" />
              <geom pos="-0.013709 0.0063957 0.024981" type="mesh" rgba="1 1 1 1" mesh="ring_link4" contype="1" conaffinity="0" density="0" group="1" class="visualgeom" />
              <geom type="mesh" rgba="1 1 1 1" mesh="ring_link4" pos="-0.013709 0.0063957 0.024981" />
            </body>
          </body>
        </body>
      </body>
      <body name="little_link0" pos="-0.02467 0.038102 0.14521">
        <inertial pos="0.00582427 5.60668e-07 0.0022475" quat="0.355185 0.355185 -0.611427 0.611427" mass="0.000858839" diaginertia="4.34042e-08 3.21335e-08 2.50587e-08" />
        <joint name="little_joint0" pos="0 0 0" axis="1 0 0" range="-0.26 0.26" actuatorfrcrange="-100 100" />
        <geom type="mesh" rgba="1 1 1 1" mesh="little_link0" contype="1" conaffinity="0" density="0" group="1" class="visualgeom" />
        <geom type="mesh" rgba="1 1 1 1" mesh="little_link0" />
        <body name="little_link1" pos="0.011115 -0.0047959 0">
          <inertial pos="-0.000683358 0.0048078 0.0243018" quat="0.707513 -0.00568489 -0.0058791 0.706653" mass="0.00458484" diaginertia="7.20267e-07 7.10516e-07 1.385e-07" />
          <joint name="little_joint1" pos="0 0 0" axis="0 1 0" range="0 1.57" actuatorfrcrange="-100 100" />
          <geom type="mesh" rgba="1 1 1 1" mesh="little_link1" contype="1" conaffinity="0" density="0" group="1" class="visualgeom" />
          <geom type="mesh" rgba="1 1 1 1" mesh="little_link1" />
          <body name="little_link2" pos="-0.0034454 0.0010465 0.044883">
            <inertial pos="0.00281619 0.00381383 0.0165996" quat="0.999163 2.62805e-05 0.0409006 -6.95714e-05" mass="0.00240942" diaginertia="2.39031e-07 1.8348e-07 9.72399e-08" />
            <joint name="little_joint2" pos="0 0 0" axis="0 1 0" range="0 1.57" actuatorfrcrange="-100 100" />
            <geom type="mesh" rgba="1 1 1 1" mesh="little_link2" contype="1" conaffinity="0" density="0" group="1" class="visualgeom" />
            <geom type="mesh" rgba="1 1 1 1" mesh="little_link2" />
            <body name="little_link3" pos="0.0084126 -0.0012 0.03069">
              <inertial pos="-0.00677812 0.00520865 0.00972346" quat="0.992008 3.57829e-05 -0.126178 -0.000281324" mass="0.00356381" diaginertia="2.50694e-07 2.44048e-07 1.13074e-07" />
              <joint name="little_joint3" pos="0 0 0" axis="0 1 0" range="0 1.57" actuatorfrcrange="-100 100" />
              <geom type="mesh" rgba="1 1 1 1" mesh="little_link3" contype="1" conaffinity="0" density="0" group="1" class="visualgeom" />
              <geom type="mesh" rgba="1 1 1 1" mesh="little_link3" />
              <geom pos="-0.013709 0.0063957 0.024981" type="mesh" rgba="1 1 1 1" mesh="little_link4" contype="1" conaffinity="0" density="0" group="1" class="visualgeom" />
              <geom type="mesh" rgba="1 1 1 1" mesh="little_link4" pos="-0.013709 0.0063957 0.024981" />
            </body>
          </body>
        </body>
      </body>
    </body>
  </worldbody>

  <actuator>
    <motor name="thumb_joint0" joint="thumb_joint0" ctrllimited="true" ctrlrange="-100 100" gear="1" />
    <motor name="thumb_joint1" joint="thumb_joint1" ctrllimited="true" ctrlrange="-100 100" gear="1" />
    <motor name="thumb_joint2" joint="thumb_joint2" ctrllimited="true" ctrlrange="-100 100" gear="1" />
    <motor name="thumb_joint3" joint="thumb_joint3" ctrllimited="true" ctrlrange="-100 100" gear="1" />
    <motor name="thumb_joint4" joint="thumb_joint4" ctrllimited="true" ctrlrange="-100 100" gear="1" />
    <motor name="index_joint0" joint="index_joint0" ctrllimited="true" ctrlrange="-100 100" gear="1" />
    <motor name="index_joint1" joint="index_joint1" ctrllimited="true" ctrlrange="-100 100" gear="1" />
    <motor name="index_joint2" joint="index_joint2" ctrllimited="true" ctrlrange="-100 100" gear="1" />
    <motor name="index_joint3" joint="index_joint3" ctrllimited="true" ctrlrange="-100 100" gear="1" />
    <motor name="middle_joint0" joint="middle_joint0" ctrllimited="true" ctrlrange="-100 100" gear="1" />
    <motor name="middle_joint1" joint="middle_joint1" ctrllimited="true" ctrlrange="-100 100" gear="1" />
    <motor name="middle_joint2" joint="middle_joint2" ctrllimited="true" ctrlrange="-100 100" gear="1" />
    <motor name="middle_joint3" joint="middle_joint3" ctrllimited="true" ctrlrange="-100 100" gear="1" />
    <motor name="ring_joint0" joint="ring_joint0" ctrllimited="true" ctrlrange="-100 100" gear="1" />
    <motor name="ring_joint1" joint="ring_joint1" ctrllimited="true" ctrlrange="-100 100" gear="1" />
    <motor name="ring_joint2" joint="ring_joint2" ctrllimited="true" ctrlrange="-100 100" gear="1" />
    <motor name="ring_joint3" joint="ring_joint3" ctrllimited="true" ctrlrange="-100 100" gear="1" />
    <motor name="little_joint0" joint="little_joint0" ctrllimited="true" ctrlrange="-100 100" gear="1" />
    <motor name="little_joint1" joint="little_joint1" ctrllimited="true" ctrlrange="-100 100" gear="1" />
    <motor name="little_joint2" joint="little_joint2" ctrllimited="true" ctrlrange="-100 100" gear="1" />
    <motor name="little_joint3" joint="little_joint3" ctrllimited="true" ctrlrange="-100 100" gear="1" />
  </actuator>

  <sensor>
    <actuatorpos name="thumb_joint0_p" actuator="thumb_joint0" />
    <actuatorvel name="thumb_joint0_v" actuator="thumb_joint0" />
    <actuatorfrc name="thumb_joint0_f" actuator="thumb_joint0" noise="0.001" />
    <actuatorpos name="thumb_joint1_p" actuator="thumb_joint1" />
    <actuatorvel name="thumb_joint1_v" actuator="thumb_joint1" />
    <actuatorfrc name="thumb_joint1_f" actuator="thumb_joint1" noise="0.001" />
    <actuatorpos name="thumb_joint2_p" actuator="thumb_joint2" />
    <actuatorvel name="thumb_joint2_v" actuator="thumb_joint2" />
    <actuatorfrc name="thumb_joint2_f" actuator="thumb_joint2" noise="0.001" />
    <actuatorpos name="thumb_joint3_p" actuator="thumb_joint3" />
    <actuatorvel name="thumb_joint3_v" actuator="thumb_joint3" />
    <actuatorfrc name="thumb_joint3_f" actuator="thumb_joint3" noise="0.001" />
    <actuatorpos name="thumb_joint4_p" actuator="thumb_joint4" />
    <actuatorvel name="thumb_joint4_v" actuator="thumb_joint4" />
    <actuatorfrc name="thumb_joint4_f" actuator="thumb_joint4" noise="0.001" />
    <actuatorpos name="index_joint0_p" actuator="index_joint0" />
    <actuatorvel name="index_joint0_v" actuator="index_joint0" />
    <actuatorfrc name="index_joint0_f" actuator="index_joint0" noise="0.001" />
    <actuatorpos name="index_joint1_p" actuator="index_joint1" />
    <actuatorvel name="index_joint1_v" actuator="index_joint1" />
    <actuatorfrc name="index_joint1_f" actuator="index_joint1" noise="0.001" />
    <actuatorpos name="index_joint2_p" actuator="index_joint2" />
    <actuatorvel name="index_joint2_v" actuator="index_joint2" />
    <actuatorfrc name="index_joint2_f" actuator="index_joint2" noise="0.001" />
    <actuatorpos name="index_joint3_p" actuator="index_joint3" />
    <actuatorvel name="index_joint3_v" actuator="index_joint3" />
    <actuatorfrc name="index_joint3_f" actuator="index_joint3" noise="0.001" />
    <actuatorpos name="middle_joint0_p" actuator="middle_joint0" />
    <actuatorvel name="middle_joint0_v" actuator="middle_joint0" />
    <actuatorfrc name="middle_joint0_f" actuator="middle_joint0" noise="0.001" />
    <actuatorpos name="middle_joint1_p" actuator="middle_joint1" />
    <actuatorvel name="middle_joint1_v" actuator="middle_joint1" />
    <actuatorfrc name="middle_joint1_f" actuator="middle_joint1" noise="0.001" />
    <actuatorpos name="middle_joint2_p" actuator="middle_joint2" />
    <actuatorvel name="middle_joint2_v" actuator="middle_joint2" />
    <actuatorfrc name="middle_joint2_f" actuator="middle_joint2" noise="0.001" />
    <actuatorpos name="middle_joint3_p" actuator="middle_joint3" />
    <actuatorvel name="middle_joint3_v" actuator="middle_joint3" />
    <actuatorfrc name="middle_joint3_f" actuator="middle_joint3" noise="0.001" />
    <actuatorpos name="ring_joint0_p" actuator="ring_joint0" />
    <actuatorvel name="ring_joint0_v" actuator="ring_joint0" />
    <actuatorfrc name="ring_joint0_f" actuator="ring_joint0" noise="0.001" />
    <actuatorpos name="ring_joint1_p" actuator="ring_joint1" />
    <actuatorvel name="ring_joint1_v" actuator="ring_joint1" />
    <actuatorfrc name="ring_joint1_f" actuator="ring_joint1" noise="0.001" />
    <actuatorpos name="ring_joint2_p" actuator="ring_joint2" />
    <actuatorvel name="ring_joint2_v" actuator="ring_joint2" />
    <actuatorfrc name="ring_joint2_f" actuator="ring_joint2" noise="0.001" />
    <actuatorpos name="ring_joint3_p" actuator="ring_joint3" />
    <actuatorvel name="ring_joint3_v" actuator="ring_joint3" />
    <actuatorfrc name="ring_joint3_f" actuator="ring_joint3" noise="0.001" />
    <actuatorpos name="little_joint0_p" actuator="little_joint0" />
    <actuatorvel name="little_joint0_v" actuator="little_joint0" />
    <actuatorfrc name="little_joint0_f" actuator="little_joint0" noise="0.001" />
    <actuatorpos name="little_joint1_p" actuator="little_joint1" />
    <actuatorvel name="little_joint1_v" actuator="little_joint1" />
    <actuatorfrc name="little_joint1_f" actuator="little_joint1" noise="0.001" />
    <actuatorpos name="little_joint2_p" actuator="little_joint2" />
    <actuatorvel name="little_joint2_v" actuator="little_joint2" />
    <actuatorfrc name="little_joint2_f" actuator="little_joint2" noise="0.001" />
    <actuatorpos name="little_joint3_p" actuator="little_joint3" />
    <actuatorvel name="little_joint3_v" actuator="little_joint3" />
    <actuatorfrc name="little_joint3_f" actuator="little_joint3" noise="0.001" />
    <framequat name="orientation" objtype="site" noise="0.001" objname="imu" />
    <gyro name="angular-velocity" site="imu" noise="0.005" cutoff="34.9" />
  </sensor>
</mujoco>